Workbook

Sheet Read me
A1: Kestrel Plumbing & Gas Pty Ltd
A2: Example acquisition target for technical videos. Fictional.
A4: The business | B4: Commercial and residential plumbing and gas. 24 staff (18 field). One depot, 14 vans. Owner-founder, 61, wants to retire. Financial year ends 30 June. Figures in A$, ex GST.
A5: Story in the numbers | B5: Revenue up 22% in two years, but gross margin is sliding, debtor days are stretching, one builder is 21% of revenue, and the owner still works on the tools two days a week. The seller says adjusted EBITDA is about $968K. A buyer gets to about $614K.
A7: Tabs
A8: P&L | B8: Three years of statutory-style profit and loss, revenue by service line.
A9: Balance Sheet | B9: Four year-ends (FY22 opening). Cash is the balancing item; drivers (debtor days etc.) sit at the bottom.
A10: Cash Flow | B10: Indirect method, built from the P&L and balance-sheet movements. Reconciles to cash.
A11: Normalisation | B11: EBITDA add-backs: what the seller claims vs what a buyer accepts, line by line.
A12: Working Capital | B12: Debtor, creditor, WIP and stock days, NWC, the NWC peg and the completion adjustment.
A13: Valuation Bridge | B13: Enterprise value to equity: debt and debt-like items, surplus cash, NWC adjustment.
A14: Funding & DSCR | B14: Bank + vendor finance, repayments, CFADS and DSCR at the buyer price vs the seller asking price.
A15: Red Flags | B15: The diligence checks that move the price, each calculated from the statements.
A16: Video ideas | B16: Technical video ideas, each tied to a tab.
A18: Colour code
A19: Blue text | B19: Hard-coded input. Change it and everything recalculates.
A20: Black text | B20: Formula.
A21: Green text | B21: Pulled from another tab.
A22: Yellow fill | B22: Key assumption to play with on camera.
A23: Red fill | B23: A check or flag.

Sheet P&L
A1: Kestrel Plumbing & Gas Pty Ltd
A2: Profit and loss statement · years ended 30 June · A$ ex GST
A3: Kestrel Plumbing & Gas Pty Ltd is a fictional company built for teaching. Any resemblance to a real business is coincidental.
A5: A$ | B5: FY23 | C5: FY24 | D5: FY25
A6: Revenue
A7: Maintenance contracts | B7: 1147569 | C7: 1274637 | D7: 1412554 | E7: Annual service agreements, strata and commercial
A8: Reactive and emergency | B8: 1313227 | C8: 1410607 | D8: 1517550 | E8: Call-outs, after-hours
A9: Projects and new build | B9: 974802 | C9: 1150103 | D9: 1262951 | E9: Includes one builder, see Red Flags
A10: Total revenue | B10: =SUM(B7:B9) -> 3435598 | C10: =SUM(C7:C9) -> 3835347 | D10: =SUM(D7:D9) -> 4193055
A12: Cost of sales
A13: Direct labour (field staff incl. super) | B13: 1179060 | C13: 1293290 | D13: 1413026
A14: Materials | B14: 719348 | C14: 813177 | D14: 885982
A15: Subcontractors | B15: 189369 | C15: 230352 | D15: 281504
A16: Fleet running costs (fuel, rego, servicing) | B16: 120111 | C16: 131836 | D16: 141806
A17: Total cost of sales | B17: =SUM(B13:B16) -> 2207888 | C17: =SUM(C13:C16) -> 2468655 | D17: =SUM(D13:D16) -> 2722318
A19: Gross profit | B19: =B10-B17 -> 1227710 | C19: =C10-C17 -> 1366692 | D19: =D10-D17 -> 1470737
A20: Gross margin % | B20: =IF(B10=0,0,B19/B10) -> 0.35734972 | C20: =IF(C10=0,0,C19/C10) -> 0.35634116 | D20: =IF(D10=0,0,D19/D10) -> 0.35075548
A22: Operating expenses
A23: Director salary (owner, incl. super) | B23: 179021 | C23: 180774 | D23: 179546 | E23: Owner also works on the tools ~2 days/week
A24: Spouse wages (bookkeeping) | B24: 64723 | C24: 67688 | D24: 69839 | E24: Family member on payroll
A25: Office and admin wages | B25: 210797 | C25: 224138 | D25: 240235
A26: Rent: depot (paid to owner's property trust) | B26: 96160 | C26: 95853 | D26: 96055 | E26: Related-party lease
A27: Marketing and advertising | B27: 37801 | C27: 44762 | D27: 51817
A28: Insurance | B28: 41089 | C28: 45960 | D28: 49888
A29: Software and IT | B29: 22023 | C29: 25985 | D29: 30926
A30: Accounting and legal | B30: 28099 | C30: 30072 | D30: 61810 | E30: FY25 includes contract dispute with a builder
A31: Motor vehicles: owner and spouse cars | B31: 34030 | C31: 36011 | D31: 38171
A32: Telephone and utilities | B32: 19052 | C32: 19949 | D32: 21121
A33: Training and licences | B33: 11945 | C33: 13986 | D33: 15046
A34: Bad debts written off | B34: 5975 | C34: 8999 | D34: 27845
A35: Other expenses | B35: 25050 | C35: 27086 | D35: 29025
A36: Total operating expenses | B36: =SUM(B23:B35) -> 775765 | C36: =SUM(C23:C35) -> 821263 | D36: =SUM(D23:D35) -> 911324
A38: EBITDA (reported) | B38: =B19-B36 -> 451945 | C38: =C19-C36 -> 545429 | D38: =D19-D36 -> 559413
A39: EBITDA margin % | B39: =IF(B10=0,0,B38/B10) -> 0.1315477 | C39: =IF(C10=0,0,C38/C10) -> 0.14221112 | D39: =IF(D10=0,0,D38/D10) -> 0.13341418
A40: Depreciation and amortisation | B40: 58261 | C40: 65852 | D40: 74173
A41: EBIT | B41: =B38-B40 -> 393684 | C41: =C38-C40 -> 479577 | D41: =D38-D40 -> 485240
A42: Interest (equipment finance) | B42: 14016 | C42: 17016 | D42: 18990
A43: Net profit before tax | B43: =B41-B42 -> 379668 | C43: =C41-C42 -> 462561 | D43: =D41-D42 -> 466250
A44: Company tax rate | B44: 0.25 | C44: Base rate entity
A45: Income tax expense | B45: =ROUND(B43*$B$44,0) -> 94917 | C45: =ROUND(C43*$B$44,0) -> 115640 | D45: =ROUND(D43*$B$44,0) -> 116563
...

Sheet Balance Sheet
A1: Kestrel Plumbing & Gas Pty Ltd
A2: Balance sheet · as at 30 June · A$
A3: Kestrel Plumbing & Gas Pty Ltd is a fictional company built for teaching. Any resemblance to a real business is coincidental.
A5: A$ | B5: FY22 | C5: FY23 | D5: FY24 | E5: FY25
A6: Current assets
A7: Cash at bank | B7: =B38+B45-(B8+B9+B10+B11+B12+B18) -> 76631 | C7: =C38+C45-(C8+C9+C10+C11+C12+C18) -> 126307 | D7: =D38+D45-(D8+D9+D10+D11+D12+D18) -> 143808 | E7: =E38+E45-(E8+E9+E10+E11+E12+E18) -> 132827 | F7: Balancing item: equals liabilities + equity less other assets
A8: Trade debtors | B8: 522121 | C8: =ROUND('P&L'!B10*C51/365,0) -> 545931 | D8: =ROUND('P&L'!C10*D51/365,0) -> 651484 | E8: =ROUND('P&L'!D10*E51/365,0) -> 769684 | F8: Driven by debtor days
A9: Contract assets (unbilled work in progress) | B9: 41219 | C9: 47985 | D9: 62122 | E9: 84552
A10: Inventory (van and depot stock) | B10: 57138 | C10: 62109 | D10: 68402 | E10: 74286
A11: Prepayments | B11: 15959 | C11: 17975 | D11: 20040 | E11: 21874
A12: Loan to director | B12: 59972 | C12: 84661 | D12: 109495 | E12: 139259 | F12: Div 7A loan. Not an operating asset
A13: Total current assets | B13: =SUM(B7:B12) -> 773040 | C13: =SUM(C7:C12) -> 884968 | D13: =SUM(D7:D12) -> 1055351 | E13: =SUM(E7:E12) -> 1222482
A15: Non-current assets
A16: Plant, equipment and vehicles at cost | B16: 461481 | C16: =B16+C53 -> 521578 | D16: =C16+D53 -> 601158 | E16: =D16+E53 -> 690691
A17: Less accumulated depreciation | B17: -151324 | C17: =B17-'P&L'!B40 -> -209585 | D17: =C17-'P&L'!C40 -> -275437 | E17: =D17-'P&L'!D40 -> -349610
A18: Net plant, equipment and vehicles | B18: =B16+B17 -> 310157 | C18: =C16+C17 -> 311993 | D18: =D16+D17 -> 325721 | E18: =E16+E17 -> 341081
A20: TOTAL ASSETS | B20: =B13+B18 -> 1083197 | C20: =C13+C18 -> 1196961 | D20: =D13+D18 -> 1381072 | E20: =E13+E18 -> 1563563
A22: Current liabilities
A23: Trade creditors | B23: 97703 | C23: =ROUND(('P&L'!B14+'P&L'!B15)*C52/365,0) -> 94606 | D23: =ROUND(('P&L'!C14+'P&L'!C15)*D52/365,0) -> 114359 | E23: =ROUND(('P&L'!D14+'P&L'!D15)*E52/365,0) -> 115149 | F23: Materials + subcontractors x creditor days
A24: Accrued expenses | B24: 38949 | C24: 42187 | D24: 45768 | E24: 50969
A25: GST payable | B25: 52031 | C25: 58267 | D25: 64245 | E25: 71310
A26: PAYG withholding and super payable | B26: 42886 | C26: 46952 | D26: 51912 | E26: 57263
A27: Provision for annual leave | B27: 88483 | C27: 95598 | D27: 107580 | E27: 120611 | F27: Owed to staff
A28: Provision for long service leave (current) | B28: 28907 | C28: 33994 | D28: 40043 | E28: 47863
A29: Income tax payable | B29: 26839 | C29: 29971 | D29: 37940 | E29: 41033
A30: Equipment finance (current) | B30: 38207 | C30: 42096 | D30: 48009 | E30: 55078
A31: Total current liabilities | B31: =SUM(B23:B30) -> 414005 | C31: =SUM(C23:C30) -> 443671 | D31: =SUM(D23:D30) -> 509856 | E31: =SUM(E23:E30) -> 559276
A33: Non-current liabilities
A34: Provision for long service leave (non-current) | B34: 47099 | C34: 51722 | D34: 58278 | E34: 63212
A35: Equipment finance (non-current) | B35: 104467 | C35: 118422 | D35: 141817 | E35: 159806
A36: Total non-current liabilities | B36: =SUM(B34:B35) -> 151566 | C36: =SUM(C34:C35) -> 170144 | D36: =SUM(D34:D35) -> 200095 | E36: =SUM(E34:E35) -> 223018
A38: TOTAL LIABILITIES | B38: =B31+B36 -> 565571 | C38: =C31+C36 -> 613815 | D38: =D31+D36 -> 709951 | E38: =E31+E36 -> 782294
A40: NET ASSETS | B40: =B20-B38 -> 517626 | C40: =C20-C38 -> 583146 | D40: =D20-D38 -> 671121 | E40: =E20-E38 -> 781269
A42: Equity
A43: Share capital | B43: 100 | C43: 100 | D43: 100 | E43: 100 | F43: 100 ordinary shares at $1
A44: Retained earnings | B44: 517526 | C44: =B44+'P&L'!B46-C54 -> 583046 | D44: =C44+'P&L'!C46-D54 -> 671021 | E44: =D44+'P&L'!D46-E54 -> 781169
A45: TOTAL EQUITY | B45: =B43+B44 -> 517626 | C45: =C43+C44 -> 583146 | D45: =D43+D44 -> 671121 | E45: =E43+E44 -> 781269
A47: Check: net assets less equity (must be 0) | B47: =ROUND(B40-B45,0) -> 0 | C47: =ROUND(C40-C45,0) -> 0 | D47: =ROUND(D40-D45,0) -> 0 | E47: =ROUND(E40-E45,0) -> 0
A50: Drivers (change these on camera)
A51: Debtor days (on revenue) | C51: 58 | D51: 62 | E51: 67
...

Sheet Cash Flow
A1: Kestrel Plumbing & Gas Pty Ltd
A2: Cash flow statement (indirect method) · years ended 30 June · A$
A3: Kestrel Plumbing & Gas Pty Ltd is a fictional company built for teaching. Any resemblance to a real business is coincidental.
A5: A$ | B5: FY23 | C5: FY24 | D5: FY25
A6: Operating activities
A7: Net profit after tax | B7: ='P&L'!B46 -> 284751 | C7: ='P&L'!C46 -> 346921 | D7: ='P&L'!D46 -> 349687
A8: Add: depreciation | B8: ='P&L'!B40 -> 58261 | C8: ='P&L'!C40 -> 65852 | D8: ='P&L'!D40 -> 74173
A9: (Increase) in trade debtors | B9: =-('Balance Sheet'!C8-'Balance Sheet'!B8) -> -23810 | C9: =-('Balance Sheet'!D8-'Balance Sheet'!C8) -> -105553 | D9: =-('Balance Sheet'!E8-'Balance Sheet'!D8) -> -118200
A10: (Increase) in contract assets | B10: =-('Balance Sheet'!C9-'Balance Sheet'!B9) -> -6766 | C10: =-('Balance Sheet'!D9-'Balance Sheet'!C9) -> -14137 | D10: =-('Balance Sheet'!E9-'Balance Sheet'!D9) -> -22430
A11: (Increase) in inventory | B11: =-('Balance Sheet'!C10-'Balance Sheet'!B10) -> -4971 | C11: =-('Balance Sheet'!D10-'Balance Sheet'!C10) -> -6293 | D11: =-('Balance Sheet'!E10-'Balance Sheet'!D10) -> -5884
A12: (Increase) in prepayments | B12: =-('Balance Sheet'!C11-'Balance Sheet'!B11) -> -2016 | C12: =-('Balance Sheet'!D11-'Balance Sheet'!C11) -> -2065 | D12: =-('Balance Sheet'!E11-'Balance Sheet'!D11) -> -1834
A13: Increase in trade creditors | B13: ='Balance Sheet'!C23-'Balance Sheet'!B23 -> -3097 | C13: ='Balance Sheet'!D23-'Balance Sheet'!C23 -> 19753 | D13: ='Balance Sheet'!E23-'Balance Sheet'!D23 -> 790
A14: Increase in accrued expenses | B14: ='Balance Sheet'!C24-'Balance Sheet'!B24 -> 3238 | C14: ='Balance Sheet'!D24-'Balance Sheet'!C24 -> 3581 | D14: ='Balance Sheet'!E24-'Balance Sheet'!D24 -> 5201
A15: Increase in GST payable | B15: ='Balance Sheet'!C25-'Balance Sheet'!B25 -> 6236 | C15: ='Balance Sheet'!D25-'Balance Sheet'!C25 -> 5978 | D15: ='Balance Sheet'!E25-'Balance Sheet'!D25 -> 7065
A16: Increase in PAYG and super payable | B16: ='Balance Sheet'!C26-'Balance Sheet'!B26 -> 4066 | C16: ='Balance Sheet'!D26-'Balance Sheet'!C26 -> 4960 | D16: ='Balance Sheet'!E26-'Balance Sheet'!D26 -> 5351
A17: Increase in annual leave provision | B17: ='Balance Sheet'!C27-'Balance Sheet'!B27 -> 7115 | C17: ='Balance Sheet'!D27-'Balance Sheet'!C27 -> 11982 | D17: ='Balance Sheet'!E27-'Balance Sheet'!D27 -> 13031
A18: Increase in LSL provision (current) | B18: ='Balance Sheet'!C28-'Balance Sheet'!B28 -> 5087 | C18: ='Balance Sheet'!D28-'Balance Sheet'!C28 -> 6049 | D18: ='Balance Sheet'!E28-'Balance Sheet'!D28 -> 7820
A19: Increase in LSL provision (non-current) | B19: ='Balance Sheet'!C34-'Balance Sheet'!B34 -> 4623 | C19: ='Balance Sheet'!D34-'Balance Sheet'!C34 -> 6556 | D19: ='Balance Sheet'!E34-'Balance Sheet'!D34 -> 4934
A20: Increase in income tax payable | B20: ='Balance Sheet'!C29-'Balance Sheet'!B29 -> 3132 | C20: ='Balance Sheet'!D29-'Balance Sheet'!C29 -> 7969 | D20: ='Balance Sheet'!E29-'Balance Sheet'!D29 -> 3093
A21: Net cash from operating activities | B21: =SUM(B7:B20) -> 335849 | C21: =SUM(C7:C20) -> 351553 | D21: =SUM(D7:D20) -> 322797
A23: Investing activities
A24: Purchase of vans and equipment | B24: =-'Balance Sheet'!C53 -> -60097 | C24: =-'Balance Sheet'!D53 -> -79580 | D24: =-'Balance Sheet'!E53 -> -89533
A25: Net cash from investing activities | B25: =B24 -> -60097 | C25: =C24 -> -79580 | D25: =D24 -> -89533
A27: Financing activities
A28: Net equipment finance drawn / (repaid) | B28: =('Balance Sheet'!C30+'Balance Sheet'!C35)-('Balance Sheet'!B30+'Balance Sheet'!B35) -> 17844 | C28: =('Balance Sheet'!D30+'Balance Sheet'!D35)-('Balance Sheet'!C30+'Balance Sheet'!C35) -> 29308 | D28: =('Balance Sheet'!E30+'Balance Sheet'!E35)-('Balance Sheet'!D30+'Balance Sheet'!D35) -> 25058
A29: Loans to director | B29: =-('Balance Sheet'!C12-'Balance Sheet'!B12) -> -24689 | C29: =-('Balance Sheet'!D12-'Balance Sheet'!C12) -> -24834 | D29: =-('Balance Sheet'!E12-'Balance Sheet'!D12) -> -29764 | E29: Cash out to the owner, outside the P&L
A30: Dividends paid | B30: =-'Balance Sheet'!C54 -> -219231 | C30: =-'Balance Sheet'!D54 -> -258946 | D30: =-'Balance Sheet'!E54 -> -239539
A31: Net cash from financing activities | B31: =SUM(B28:B30) -> -226076 | C31: =SUM(C28:C30) -> -254472 | D31: =SUM(D28:D30) -> -244245
A33: Net change in cash | B33: =B21+B25+B31 -> 49676 | C33: =C21+C25+C31 -> 17501 | D33: =D21+D25+D31 -> -10981
A34: Opening cash | B34: ='Balance Sheet'!B7 -> 76631 | C34: ='Balance Sheet'!C7 -> 126307 | D34: ='Balance Sheet'!D7 -> 143808
A35: Closing cash | B35: =B33+B34 -> 126307 | C35: =C33+C34 -> 143808 | D35: =D33+D34 -> 132827
A36: Check: closing cash less balance sheet cash (must be 0) | B36: =ROUND(B35-'Balance Sheet'!C7,0) -> 0 | C36: =ROUND(C35-'Balance Sheet'!D7,0) -> 0 | D36: =ROUND(D35-'Balance Sheet'!E7,0) -> 0
A38: Free cash flow (operating less capex) | B38: =B21+B25 -> 275752 | C38: =C21+C25 -> 271973 | D38: =D21+D25 -> 233264
A39: Cash conversion (operating cash / EBITDA) | B39: =IF('P&L'!B38=0,0,B21/'P&L'!B38) -> 0.74311918 | C39: =IF('P&L'!C38=0,0,C21/'P&L'!C38) -> 0.64454402 | D39: =IF('P&L'!D38=0,0,D21/'P&L'!D38) -> 0.57702806
A40: Total cash to owner (dividends + director loan) | B40: =-(B29+B30) -> 243920 | C40: =-(C29+C30) -> 283780 | D40: =-(D29+D30) -> 269303

Sheet Normalisation
A1: Kestrel Plumbing & Gas Pty Ltd
A2: EBITDA normalisation · FY25 · what the seller claims vs what a buyer accepts
A3: Kestrel Plumbing & Gas Pty Ltd is a fictional company built for teaching. Any resemblance to a real business is coincidental.
A5: A$ | B5: Seller claims | C5: Buyer accepts | D5: Gap | E5: Why the buyer disagrees
A6: Reported EBITDA FY25 | B6: ='P&L'!D38 -> 559413 | C6: ='P&L'!D38 -> 559413 | D6: =B6-C6 -> 0
A8: Adjustments
A9: Owner salary | B9: ='P&L'!D23 -> 179546 | C9: 19893 | D9: =B9-C9 -> 159653 | E9: A replacement general manager costs about $160K. Only the excess over market is an add-back, not the whole salary.
A10: Spouse wages | B10: ='P&L'!D24 -> 69839 | C10: 0 | D10: =B10-C10 -> 69839 | E10: She does the books. Replacing her costs about $75K, so nothing comes back.
A11: Rent above market (related party) | B11: 23856 | C11: 23900 | D11: =B11-C11 -> -44 | E11: Market rent for the depot is about $72K. Accepted only if a new lease at market is signed at completion.
A12: Owner and spouse cars | B12: ='P&L'!D31 -> 38171 | C12: 25876 | D12: =B12-C12 -> 12295 | E12: The ute is used for site visits; about $12K stays as a real cost.
A13: One-off legal dispute | B13: 29951 | C13: 29829 | D13: =B13-C13 -> 122 | E13: Genuinely one-off: the dispute is settled. Accepted with the settlement deed.
A14: Bad debt spike | B14: 22099 | C14: 0 | D14: =B14-C14 -> 22099 | E14: The builder who didn't pay is still 21% of revenue. Risk of a repeat.
A15: Price rise from 1 July (pro forma) | B15: 45062 | C15: 0 | D15: =B15-C15 -> 45062 | E15: Not earned yet. Buyers pay for history, not a promise.
A16: Owner on the tools 2 days a week | B16: 0 | C16: -44810 | D16: =B16-C16 -> 44810 | E16: When the owner leaves, a technician must be hired. This adjustment goes the other way.
A17: Total adjustments | B17: =SUM(B9:B16) -> 408524 | C17: =SUM(C9:C16) -> 54688 | D17: =B17-C17 -> 353836
A19: Adjusted EBITDA FY25 | B19: =B6+B17 -> 967937 | C19: =C6+C17 -> 614101 | D19: =B19-C19 -> 353836
A21: Multiple | B21: 4 | C21: 4
A22: Implied enterprise value | B22: =B19*B21 -> 3871748 | C22: =C19*C21 -> 2456404 | D22: =B22-C22 -> 1415344
A24: Same multiple, different EBITDA. The argument is never about the multiple first; it is about which add-backs are real.

Sheet Working Capital
A1: Kestrel Plumbing & Gas Pty Ltd
A2: Net working capital · as at 30 June · A$
A3: Kestrel Plumbing & Gas Pty Ltd is a fictional company built for teaching. Any resemblance to a real business is coincidental.
A5: A$ | B5: FY22 | C5: FY23 | D5: FY24 | E5: FY25
A6: Operating working capital
A7: Trade debtors | B7: ='Balance Sheet'!B8 -> 522121 | C7: ='Balance Sheet'!C8 -> 545931 | D7: ='Balance Sheet'!D8 -> 651484 | E7: ='Balance Sheet'!E8 -> 769684
A8: Contract assets | B8: ='Balance Sheet'!B9 -> 41219 | C8: ='Balance Sheet'!C9 -> 47985 | D8: ='Balance Sheet'!D9 -> 62122 | E8: ='Balance Sheet'!E9 -> 84552
A9: Inventory | B9: ='Balance Sheet'!B10 -> 57138 | C9: ='Balance Sheet'!C10 -> 62109 | D9: ='Balance Sheet'!D10 -> 68402 | E9: ='Balance Sheet'!E10 -> 74286
A10: Prepayments | B10: ='Balance Sheet'!B11 -> 15959 | C10: ='Balance Sheet'!C11 -> 17975 | D10: ='Balance Sheet'!D11 -> 20040 | E10: ='Balance Sheet'!E11 -> 21874
A11: Less trade creditors | B11: =-'Balance Sheet'!B23 -> -97703 | C11: =-'Balance Sheet'!C23 -> -94606 | D11: =-'Balance Sheet'!D23 -> -114359 | E11: =-'Balance Sheet'!E23 -> -115149
A12: Less accrued expenses | B12: =-'Balance Sheet'!B24 -> -38949 | C12: =-'Balance Sheet'!C24 -> -42187 | D12: =-'Balance Sheet'!D24 -> -45768 | E12: =-'Balance Sheet'!E24 -> -50969
A13: Less GST payable | B13: =-'Balance Sheet'!B25 -> -52031 | C13: =-'Balance Sheet'!C25 -> -58267 | D13: =-'Balance Sheet'!D25 -> -64245 | E13: =-'Balance Sheet'!E25 -> -71310
A14: Less PAYG and super payable | B14: =-'Balance Sheet'!B26 -> -42886 | C14: =-'Balance Sheet'!C26 -> -46952 | D14: =-'Balance Sheet'!D26 -> -51912 | E14: =-'Balance Sheet'!E26 -> -57263
A15: Net working capital | B15: =SUM(B7:B14) -> 404868 | C15: =SUM(C7:C14) -> 431988 | D15: =SUM(D7:D14) -> 525764 | E15: =SUM(E7:E14) -> 655705
A16: NWC as % of revenue | C16: =IF('P&L'!B10=0,0,C15/'P&L'!B10) -> 0.12573881 | D16: =IF('P&L'!C10=0,0,D15/'P&L'!C10) -> 0.13708382 | E16: =IF('P&L'!D10=0,0,E15/'P&L'!D10) -> 0.15637882
A17: Excluded on purpose: cash, director loan, tax payable, leave provisions, equipment finance (cash or debt-like, see Valuation Bridge).
A19: Days
A20: Debtor days | C20: =C7/'P&L'!B10*365 -> 58.000038 | D20: =D7/'P&L'!C10*365 -> 62.000038 | E20: =E7/'P&L'!D10*365 -> 66.999994
A21: WIP days (on revenue) | C21: =C8/'P&L'!B10*365 -> 5.0979553 | D21: =D8/'P&L'!C10*365 -> 5.9119892 | E21: =E8/'P&L'!D10*365 -> 7.3601419
A22: Stock days (on materials) | C22: =C9/'P&L'!B14*365 -> 31.51435 | D22: =D9/'P&L'!C14*365 -> 30.702701 | E22: =E9/'P&L'!D14*365 -> 30.603771
A23: Creditor days (on materials + subcontractors) | C23: =-C11/('P&L'!B14+'P&L'!B15)*365 -> 37.999938 | D23: =-D11/('P&L'!C14+'P&L'!C15)*365 -> 39.99988 | E23: =-E11/('P&L'!D14+'P&L'!D15)*365 -> 35.999905
A24: Cash conversion cycle | C24: =C20+C21+C22-C23 -> 56.612406 | D24: =D20+D21+D22-D23 -> 58.614848 | E24: =E20+E21+E22-E23 -> 68.964002
A26: NWC peg and completion adjustment
A27: Peg: average NWC % of revenue, FY23–FY25 | E27: =AVERAGE(C16:E16) -> 0.13973382
A28: Peg in dollars (on FY25 revenue) | E28: =E27*'P&L'!D10 -> 585911.57
A29: NWC delivered at completion (FY25 close) | E29: =E15 -> 655705
A30: Completion adjustment (+ buyer pays more / − price falls) | E30: =E29-E28 -> 69793.427
A32: Every extra debtor day at FY25 revenue ties up about this much cash: | E32: ='P&L'!D10/365 -> 11487.822

Sheet Valuation Bridge
A1: Kestrel Plumbing & Gas Pty Ltd
A2: Enterprise value to equity value · cash-free, debt-free · A$
A3: Kestrel Plumbing & Gas Pty Ltd is a fictional company built for teaching. Any resemblance to a real business is coincidental.
A5: A$ | B5: Buyer view | C5: Seller view | D5: Note
A6: Adjusted EBITDA FY25 | B6: =Normalisation!C19 -> 614101 | C6: =Normalisation!B19 -> 967937
A7: Multiple | B7: =Normalisation!C21 -> 4 | C7: =Normalisation!B21 -> 4
A8: Enterprise value | B8: =B6*B7 -> 2456404 | C8: =C6*C7 -> 3871748
A10: Less debt and debt-like items
A11: Equipment finance | B11: =-('Balance Sheet'!E30+'Balance Sheet'!E35) -> -214884 | C11: =-('Balance Sheet'!E30+'Balance Sheet'!E35) -> -214884 | D11: Real debt. Always comes off.
A12: Long service leave owed to staff | B12: =-('Balance Sheet'!E28+'Balance Sheet'!E34) -> -111075 | C12: 0 | D12: Seller says it's part of the business. Buyer says it's a debt the seller built up.
A13: Annual leave owed to staff | B13: =-'Balance Sheet'!E27 -> -120611 | C13: 0 | D13: Often negotiated: sometimes in NWC, sometimes debt-like.
A14: Income tax payable | B14: =-'Balance Sheet'!E29 -> -41033 | C14: =-'Balance Sheet'!E29 -> -41033 | D14: Tax on profits the seller already earned.
A15: Director loan settled before completion | B15: 0 | C15: 0 | D15: Excluded: the $140K Div 7A loan must be repaid or cleared by the seller, not bought.
A16: Total debt and debt-like | B16: =SUM(B11:B15) -> -487603 | C16: =SUM(C11:C15) -> -255917
A18: Plus cash and working capital
A19: Minimum operating cash left in the business | B19: 100000 | C19: 100000 | D19: Cash needed to run payroll; not a bonus for the seller.
A20: Surplus cash paid to seller | B20: =MAX(0,'Balance Sheet'!E7-B19) -> 32827 | C20: =MAX(0,'Balance Sheet'!E7-C19) -> 32827
A21: NWC adjustment vs peg | B21: ='Working Capital'!E30 -> 69793.427 | C21: 0 | D21: Seller ignores the peg. Buyer applies it.
A23: Equity value (price for the shares) | B23: =B8+B16+B20+B21 -> 2071421.4 | C23: =C8+C16+C20+C21 -> 3648658
A24: Gap between the two views | B24: =C23-B23 -> 1577236.6

Sheet Funding & DSCR
A1: Kestrel Plumbing & Gas Pty Ltd
A2: How the deal is paid for, and whether the business can carry it · A$
A3: Kestrel Plumbing & Gas Pty Ltd is a fictional company built for teaching. Any resemblance to a real business is coincidental.
A5: A$ | B5: Seller asking | C5: Buyer price | D5: Buyer price, restructured | E5: Note
A6: Enterprise value (purchase price) | B6: ='Valuation Bridge'!C8 -> 3871748 | C6: ='Valuation Bridge'!B8 -> 2456404 | D6: ='Valuation Bridge'!B8 -> 2456404 | E6: Column 3 keeps the buyer price and changes only the terms.
A8: Funding stack
A9: Bank share of price | B9: 0.6 | C9: 0.6 | D9: 0.4
A10: Vendor finance share of price | B10: 0.4 | C10: 0.4 | D10: 0.6
A11: Buyer cash | B11: =1-B9-B10 -> 0 | C11: =1-C9-C10 -> 0 | D11: =1-D9-D10 -> 0 | E11: No money down when this is 0%
A12: Bank loan | B12: =B6*B9 -> 2323048.8 | C12: =C6*C9 -> 1473842.4 | D12: =D6*D9 -> 982561.6
A13: Vendor loan | B13: =B6*B10 -> 1548699.2 | C13: =C6*C10 -> 982561.6 | D13: =D6*D10 -> 1473842.4
A15: Terms
A16: Bank rate | B16: 0.085 | C16: 0.085 | D16: 0.085
A17: Bank term (years) | B17: 5 | C17: 5 | D17: 10
A18: Vendor rate | B18: 0.04 | C18: 0.04 | D18: 0.04
A19: Vendor term (years) | B19: 7 | C19: 7 | D19: 15 | E19: Long vendor terms are what make the deal carry.
A20: Bank repayment per year (P&I) | B20: =PMT(B16,B17,-B12) -> 589510.23 | C20: =PMT(C16,C17,-C12) -> 374010.72 | D20: =PMT(D16,D17,-D12) -> 149749.96
A21: Vendor repayment per year (P&I) | B21: =PMT(B18,B19,-B13) -> 258028.17 | C21: =PMT(C18,C19,-C13) -> 163704.21 | D21: =PMT(D18,D19,-D13) -> 132559.01
A22: Total debt service | B22: =B20+B21 -> 847538.4 | C22: =C20+C21 -> 537714.93 | D22: =D20+D21 -> 282308.97
A24: Cash available for debt service (year 1)
A25: Adjusted EBITDA (buyer view in every column) | B25: ='Valuation Bridge'!B6 -> 614101 | C25: ='Valuation Bridge'!B6 -> 614101 | D25: ='Valuation Bridge'!B6 -> 614101 | E25: The bank lends on real EBITDA, whatever price you agree.
A26: Less maintenance capex (3-yr average) | B26: =-ROUND(AVERAGE('Balance Sheet'!C53:E53),0) -> -76403 | C26: =-ROUND(AVERAGE('Balance Sheet'!C53:E53),0) -> -76403 | D26: =-ROUND(AVERAGE('Balance Sheet'!C53:E53),0) -> -76403
A27: Less tax (EBITDA less D&A less year-1 interest, x rate) | B27: =-ROUND(MAX(0,(B25-'P&L'!D40-B12*B16-B13*B18)*'P&L'!$B$44),0) -> -70130 | C27: =-ROUND(MAX(0,(C25-'P&L'!D40-C12*C16-C13*C18)*'P&L'!$B$44),0) -> -93837 | D27: =-ROUND(MAX(0,(D25-'P&L'!D40-D12*D16-D13*D18)*'P&L'!$B$44),0) -> -99364
A28: CFADS | B28: =SUM(B25:B27) -> 467568 | C28: =SUM(C25:C27) -> 443861 | D28: =SUM(D25:D27) -> 438334
A30: DSCR (CFADS / debt service) | B30: =IF(B22=0,0,B28/B22) -> 0.55167766 | C30: =IF(C22=0,0,C28/C22) -> 0.82545783 | D30: =IF(D22=0,0,D28/D22) -> 1.5526747
A31: Target DSCR | B31: 1.5 | C31: 1.5 | D31: 1.5
A32: Verdict | B32: =IF(B30>=B31,"Fundable","Fails") -> Fails | C32: =IF(C30>=C31,"Fundable","Fails") -> Fails | D32: =IF(D30>=D31,"Fundable","Fails") -> Fundable
A34: What the business can carry
A35: Max debt service at target DSCR | B35: =B28/B31 -> 311712 | C35: =C28/C31 -> 295907.33 | D35: =D28/D31 -> 292222.67
A36: Headroom / (shortfall) per year | B36: =B35-B22 -> -535826.4 | C36: =C35-C22 -> -241807.6 | D36: =D35-D22 -> 9913.7009

Sheet Red Flags
A1: Kestrel Plumbing & Gas Pty Ltd
A2: Diligence checks calculated from the statements
A3: Kestrel Plumbing & Gas Pty Ltd is a fictional company built for teaching. Any resemblance to a real business is coincidental.
A5: A$ | B5: FY23 | C5: FY24 | D5: FY25 | E5: Why it matters
A6: Largest customer revenue (one builder) | B6: 638097 | C6: 778572 | D6: 898533 | E6: Input: from the aged debtors and sales ledger.
A7: Largest customer % of revenue | B7: =B6/'P&L'!B10 -> 0.18573098 | C7: =C6/'P&L'!C10 -> 0.2029991 | D7: =D6/'P&L'!D10 -> 0.21429077 | E7: Over 20% and rising. Lose the builder and about a fifth of revenue goes with it.
A8: Revenue growth | C8: ='P&L'!C10/'P&L'!B10-1 -> 0.116355 | D8: ='P&L'!D10/'P&L'!C10-1 -> 0.093266137 | E8: Healthy top line. The question is what kind of revenue.
A9: Gross margin | B9: ='P&L'!B20 -> 0.35734972 | C9: ='P&L'!C20 -> 0.35634116 | D9: ='P&L'!D20 -> 0.35075548 | E9: Falling every year while projects grow. Projects work for the builder is probably low margin.
A10: Debtor days | B10: ='Working Capital'!C20 -> 58.000038 | C10: ='Working Capital'!D20 -> 62.000038 | D10: ='Working Capital'!E20 -> 66.999994 | E10: Stretching. Customers are paying slower, and the builder is the likely cause.
A11: Bad debts % of revenue | B11: ='P&L'!B34/'P&L'!B10 -> 0.0017391441 | C11: ='P&L'!C34/'P&L'!C10 -> 0.0023463327 | D11: ='P&L'!D34/'P&L'!D10 -> 0.0066407428 | E11: Tripled in FY25. Same customer as the legal dispute.
A12: Cash conversion (operating cash / EBITDA) | B12: ='Cash Flow'!B39 -> 0.74311918 | C12: ='Cash Flow'!C39 -> 0.64454402 | D12: ='Cash Flow'!D39 -> 0.57702806 | E12: Below 80% means profit is turning into debtors, not cash.
A13: Cash taken by owner (dividends + director loan) | B13: ='Cash Flow'!B40 -> 243920 | C13: ='Cash Flow'!C40 -> 283780 | D13: ='Cash Flow'!D40 -> 269303 | E13: Compare with free cash flow. Is the owner taking more than the business makes?
A14: Free cash flow | B14: ='Cash Flow'!B38 -> 275752 | C14: ='Cash Flow'!C38 -> 271973 | D14: ='Cash Flow'!D38 -> 233264
A15: Loan to director (Div 7A) | B15: ='Balance Sheet'!C12 -> 84661 | C15: ='Balance Sheet'!D12 -> 109495 | D15: ='Balance Sheet'!E12 -> 139259 | E15: Cash leaving the business without going through the P&L. Must be cleared before completion.
A16: Staff leave owed (annual + long service) | B16: ='Balance Sheet'!C27+'Balance Sheet'!C28+'Balance Sheet'!C34 -> 181314 | C16: ='Balance Sheet'!D27+'Balance Sheet'!D28+'Balance Sheet'!D34 -> 205901 | D16: ='Balance Sheet'!E27+'Balance Sheet'!E28+'Balance Sheet'!E34 -> 231686 | E16: Unfunded promise to staff. Who pays it is a price negotiation.
A17: Related-party rent | B17: ='P&L'!B26 -> 96160 | C17: ='P&L'!C26 -> 95853 | D17: ='P&L'!D26 -> 96055 | E17: Paid to the owner's trust, above market. Needs a new lease at market rent at completion.
A18: Owner salary as % of EBITDA | B18: ='P&L'!B23/'P&L'!B38 -> 0.39611236 | C18: ='P&L'!C23/'P&L'!C38 -> 0.33143452 | D18: ='P&L'!D23/'P&L'!D38 -> 0.32095429 | E18: And the owner is on the tools two days a week. A buyer has to replace both jobs.

Sheet Video ideas
A1: Technical videos from this one target
A3: Title | B3: Tab | C3: What to show on screen
A4: The Seller Said $968K EBITDA. I Got $614K. (Add-Back Teardown) | B4: Normalisation | C4: Go line by line: which add-backs survive and why. End on the $1.4M valuation gap.
A5: If You Can't Read A Balance Sheet, You Can't Buy A Business | B5: Balance Sheet | C5: Walk top to bottom: what each line means for a buyer, then the 3 lines that change the price.
A6: Enterprise Value vs Equity Value: Where $500K Disappears At Settlement | B6: Valuation Bridge | C6: Same business, two bridges. Debt-like items, leave provisions, surplus cash.
A7: The Most Valuable Working Capital Training You'll Ever Watch (The NWC Peg) | B7: Working Capital | C7: Build the peg live, then change debtor days by 10 and show what it costs at completion.
A8: Every Line Of A P&L A Buyer Questions (Real Example) | B8: P&L | C8: Owner salary, family wages, related-party rent, bad debts, legal. What each hides.
A9: Profit Isn't Cash: Reading A Cash Flow Statement Like A Buyer | B9: Cash Flow | C9: Profit vs operating cash, cash conversion, and cash quietly taken by the owner.
A10: DSCR Explained With A Real Deal: Same Price, Different Terms, Different Answer | B10: Funding & DSCR | C10: Three columns: seller price fails, buyer price on standard terms fails, buyer price on restructured terms passes 1.5×.
A11: 11 Red Flags Hiding In A $4.2M Business's Financials | B11: Red Flags | C11: One by one, each calculated from the statements.
A12: What Is A Div 7A Loan, And Why It Matters When You Buy | B12: Balance Sheet | C12: The $140K loan to the director, and how to clear it before completion.
A13: Annual Leave, Long Service Leave: The $230K Debt Nobody Puts In The Price | B13: Valuation Bridge | C13: Who pays accrued leave, and how it changes the price.
A14: Watch Me Price This $4.2M Plumbing Business Live (Full Model) | B14: All tabs | C14: End to end in one sitting: P&L, normalise, bridge, fund, DSCR.
A15: Gross Margin Is Falling And Revenue Is Rising. Here's Why That's A Problem | B15: P&L / Red Flags | C15: Mix shift to projects for one builder; the margin story behind growth.
